Workbook

Sheet Allocation
A2: Client Profile
A4: Field | B4: Value
A5: effective_risk_score | B5: 7.5
A6: age | B6: 50
A7: annual_income | B7: 0
A8: osi | B8: 0 | G8: Actual
A9: savings_rate_adjustment | B9: none | F9: A | G9: =G11+G17 -> 100000 | J9: =G9 -> 100000
A10: gap_exceeds_3 | B10: FALSE | R10: 60000 | S10: =J9+SUM(N10:R10) -> 160000
A11: shortfall_amount | B11: 0 | F11: Equity | G11: 75000 | H11: =G11/$G$9 -> 0.75 | I11: =F11 -> Equity | J11: 0.65 | K11: =J11*$J$9 -> 65000 | M11: =K11-G11 -> -10000 | R11: =S11-G11 -> 29000 | S11: =J11*$S$10 -> 104000
A12: total_corpus | B12: =C260 -> 10000000 | F12: Large | G12: 45000 | H12: =G12/$G$9 -> 0.45 | I12: =F12 -> Large | J12: 0.25 | K12: =J12*$J$9 -> 25000 | M12: =K12-G12 -> -20000 | R12: =S12-G12 -> -5000 | S12: =J12*$S$10 -> 40000
A13: monthly_household_expense | B13: 60000 | F13: HDFC | G13: =G11-G15 -> 45000 | H13: =G13/$G$9 -> 0.45 | I13: ICICI Large | J13: =J12 -> 0.25 | K13: =J13*$J$9 -> 25000 | M13: =K13 -> 25000 | R13: =S13-G13 -> -5000 | S13: =J13*$S$10 -> 40000
A14: tax_regime | B14: old | F14: Small | G14: 30000 | H14: =G14/$G$9 -> 0.3 | I14: =F14 -> Small | J14: =J11-J12 -> 0.4 | K14: =J14*$J$9 -> 40000 | M14: =K14-G14 -> 10000 | R14: =S14-G14 -> 34000 | S14: =J14*$S$10 -> 64000
A15: section_80c_utilized | B15: 100000 | F15: Frank | G15: 30000 | H15: =G15/$G$9 -> 0.3 | I15: Bandhan | J15: =J14 -> 0.4 | K15: =J15*$J$9 -> 40000 | R15: =S15-G15 -> 34000 | S15: =J15*$S$10 -> 64000
A16: emergency_fund_needed | B16: TRUE | S16: =J16*$S$10 -> 0
A17: primary_income_from_portfolio | B17: FALSE | F17: Debt | G17: =G18 -> 25000 | H17: =G17/$G$9 -> 0.25 | I17: =F17 -> Debt | J17: =1-J11 -> 0.35 | K17: =J17*$J$9 -> 35000 | M17: =K17-G17 -> 10000 | R17: =S17-G17 -> 31000 | S17: =J17*$S$10 -> 56000
A18: effective_tax_rate | B18: 15 | F18: ICICI debt | G18: 25000 | H18: =G18/$G$9 -> 0.25 | I18: =F18 -> ICICI debt | J18: =J17 -> 0.35 | K18: =J18*$J$9 -> 35000 | M18: =K18-G18 -> 10000 | R18: =S18-G18 -> 31000 | S18: =J18*$S$10 -> 56000
A19: risk_willingness | B19: 7
A20: risk_capacity_score | B20: 9
A21: net_financial_assets | B21: =B12 -> 10000000
A22: occupation_type | B22: public_sector
A23: Round to 100/ 1000 | B23: -2
A24: multi_asset_equity_pct | B24: 65
A25: multi_asset_debt_pct | B25: 25
A26: multi_asset_others_pct | B26: 10
A27: multi_asset_max_equity | B27: 0.5
A30: Goals
A32: goal_type | B32: goal_period_min | C32: goal_period_max
A33: short_term_goal | B33: 0 | C33: 24
A34: medium_term_goal_3 | B34: =C33+1 -> 25 | C34: =5*12 -> 60
A35: medium_term_goal_4
A36: medium_term_goal_5
A37: long_term_goal | B37: =C34+1 -> 61
A40: goal_name | B40: time_to_goal_months | C40: goal_type | D40: goal_year | E40: amount_needed | F40: goal_priority | G40: investment_goal | H40: goal_year
A41: Home | B41: 60 | C41: =IF(A41="","",IF(B41<$C$33,$A$33,IF(B41>$C$34,$A$37,$A$34))) -> medium_term_goal_3 | D41: =IF(B41="","",ROUNDUP(B41/12,0)) -> 5 | E41: =25*10^5 -> 2500000 | F41: negotiable | G41: wealth_creation
A42: Child Education | B42: 12 | C42: =IF(A42="","",IF(B42<$C$33,$A$33,IF(B42>$C$34,$A$37,$A$34))) -> short_term_goal | D42: =IF(B42="","",ROUNDUP(B42/12,0)) -> 1 | E42: =3*10^5 -> 300000 | F42: negotiable | G42: other
A43: Retirement | B43: 180 | C43: =IF(A43="","",IF(B43<$C$33,$A$33,IF(B43>$C$34,$A$37,$A$34))) -> long_term_goal | D43: =IF(B43="","",ROUNDUP(B43/12,0)) -> 15 | E43: 20000000 | F43: non_negotiable | G43: retirement
C44: =IF(A44="","",IF(B44<$C$33,$A$33,IF(B44>$C$34,$A$37,$A$34))) | D44: =IF(B44="","",ROUNDUP(B44/12,0)) | E44: =IF(C44="","",IF(D44<$C$33,$A$33,IF(D44>$C$34,$A$37,$A$34))) | F44: =IF(D44="","",IF(E44<$C$33,$A$33,IF(E44>$C$34,$A$37,$A$34)))
C45: =IF(A45="","",IF(B45<$C$33,$A$33,IF(B45>$C$34,$A$37,$A$34))) | D45: =IF(B45="","",ROUNDUP(B45/12,0)) | E45: =IF(C45="","",IF(D45<$C$33,$A$33,IF(D45>$C$34,$A$37,$A$34))) | F45: =IF(D45="","",IF(E45<$C$33,$A$33,IF(E45>$C$34,$A$37,$A$34)))
C46: =IF(A46="","",IF(B46<$C$33,$A$33,IF(B46>$C$34,$A$37,$A$34))) | D46: =IF(B46="","",ROUNDUP(B46/12,0)) | E46: =IF(C46="","",IF(D46<$C$33,$A$33,IF(D46>$C$34,$A$37,$A$34))) | F46: =IF(D46="","",IF(E46<$C$33,$A$33,IF(E46>$C$34,$A$37,$A$34)))
C47: =IF(A47="","",IF(B47<$C$33,$A$33,IF(B47>$C$34,$A$37,$A$34))) | D47: =IF(B47="","",ROUNDUP(B47/12,0))
...

Sheet Allocation 2
A2: Client Profile
A4: Field | B4: Value
A5: effective_risk_score | B5: 5.5
A6: age | B6: 50
A7: annual_income | B7: 0
A8: osi | B8: 0 | G8: Actual
A9: savings_rate_adjustment | B9: none | F9: A | G9: =G11+G17 -> 100000 | J9: =G9 -> 100000
A10: gap_exceeds_3 | B10: FALSE | R10: 60000 | S10: =J9+SUM(N10:R10) -> 160000
A11: shortfall_amount | B11: 0 | F11: Equity | G11: 75000 | H11: =G11/$G$9 -> 0.75 | I11: =F11 -> Equity | J11: 0.65 | K11: =J11*$J$9 -> 65000 | M11: =K11-G11 -> -10000 | R11: =S11-G11 -> 29000 | S11: =J11*$S$10 -> 104000
A12: total_corpus | B12: 8000000 | F12: Large | G12: 45000 | H12: =G12/$G$9 -> 0.45 | I12: =F12 -> Large | J12: 0.25 | K12: =J12*$J$9 -> 25000 | M12: =K12-G12 -> -20000 | R12: =S12-G12 -> -5000 | S12: =J12*$S$10 -> 40000
A13: monthly_household_expense | B13: 60000 | F13: HDFC | G13: =G11-G15 -> 45000 | H13: =G13/$G$9 -> 0.45 | I13: ICICI Large | J13: =J12 -> 0.25 | K13: =J13*$J$9 -> 25000 | M13: =K13 -> 25000 | R13: =S13-G13 -> -5000 | S13: =J13*$S$10 -> 40000
A14: tax_regime | B14: old | F14: Small | G14: 30000 | H14: =G14/$G$9 -> 0.3 | I14: =F14 -> Small | J14: =J11-J12 -> 0.4 | K14: =J14*$J$9 -> 40000 | M14: =K14-G14 -> 10000 | R14: =S14-G14 -> 34000 | S14: =J14*$S$10 -> 64000
A15: section_80c_utilized | B15: 100000 | F15: Frank | G15: 30000 | H15: =G15/$G$9 -> 0.3 | I15: Bandhan | J15: =J14 -> 0.4 | K15: =J15*$J$9 -> 40000 | R15: =S15-G15 -> 34000 | S15: =J15*$S$10 -> 64000
A16: emergency_fund_needed | B16: TRUE | S16: =J16*$S$10 -> 0
A17: primary_income_from_portfolio | B17: FALSE | F17: Debt | G17: =G18 -> 25000 | H17: =G17/$G$9 -> 0.25 | I17: =F17 -> Debt | J17: =1-J11 -> 0.35 | K17: =J17*$J$9 -> 35000 | M17: =K17-G17 -> 10000 | R17: =S17-G17 -> 31000 | S17: =J17*$S$10 -> 56000
A18: effective_tax_rate | B18: 15 | F18: ICICI debt | G18: 25000 | H18: =G18/$G$9 -> 0.25 | I18: =F18 -> ICICI debt | J18: =J17 -> 0.35 | K18: =J18*$J$9 -> 35000 | M18: =K18-G18 -> 10000 | R18: =S18-G18 -> 31000 | S18: =J18*$S$10 -> 56000
A19: risk_willingness | B19: 7
A20: risk_capacity_score | B20: 9
A21: net_financial_assets | B21: =B12 -> 8000000
A22: occupation_type | B22: public_sector
A23: Round to 100/ 1000 | B23: -2
A24: multi_asset_equity_pct | B24: 65
A25: multi_asset_debt_pct | B25: 25
A26: multi_asset_others_pct | B26: 10
A27: multi_asset_max_equity | B27: 0.5
A30: Goals
A32: goal_type | B32: goal_period_min | C32: goal_period_max
A33: short_term_goal | B33: 0 | C33: 24
A34: medium_term_goal_3 | B34: =C33+1 -> 25 | C34: =5*12 -> 60
A35: medium_term_goal_4
A36: medium_term_goal_5
A37: long_term_goal | B37: =C34+1 -> 61
A40: goal_name | B40: time_to_goal_months | C40: goal_type | D40: goal_year | E40: amount_needed | F40: goal_priority | G40: investment_goal | H40: goal_year
A41: Home | B41: 60 | C41: =IF(A41="","",IF(B41<$C$33,$A$33,IF(B41>$C$34,$A$37,$A$34))) -> medium_term_goal_3 | D41: =IF(B41="","",ROUNDUP(B41/12,0)) -> 5 | E41: =25*10^5 -> 2500000 | F41: negotiable | G41: wealth_creation
A42: Child Education | B42: 12 | C42: =IF(A42="","",IF(B42<$C$33,$A$33,IF(B42>$C$34,$A$37,$A$34))) -> short_term_goal | D42: =IF(B42="","",ROUNDUP(B42/12,0)) -> 1 | E42: =3*10^5 -> 300000 | F42: negotiable | G42: other
A43: Retirement | B43: 180 | C43: =IF(A43="","",IF(B43<$C$33,$A$33,IF(B43>$C$34,$A$37,$A$34))) -> long_term_goal | D43: =IF(B43="","",ROUNDUP(B43/12,0)) -> 15 | E43: 20000000 | F43: non_negotiable | G43: retirement
C44: =IF(A44="","",IF(B44<$C$33,$A$33,IF(B44>$C$34,$A$37,$A$34))) | D44: =IF(B44="","",ROUNDUP(B44/12,0)) | E44: =IF(C44="","",IF(D44<$C$33,$A$33,IF(D44>$C$34,$A$37,$A$34))) | F44: =IF(D44="","",IF(E44<$C$33,$A$33,IF(E44>$C$34,$A$37,$A$34)))
C45: =IF(A45="","",IF(B45<$C$33,$A$33,IF(B45>$C$34,$A$37,$A$34))) | D45: =IF(B45="","",ROUNDUP(B45/12,0)) | E45: =IF(C45="","",IF(D45<$C$33,$A$33,IF(D45>$C$34,$A$37,$A$34))) | F45: =IF(D45="","",IF(E45<$C$33,$A$33,IF(E45>$C$34,$A$37,$A$34)))
C46: =IF(A46="","",IF(B46<$C$33,$A$33,IF(B46>$C$34,$A$37,$A$34))) | D46: =IF(B46="","",ROUNDUP(B46/12,0)) | E46: =IF(C46="","",IF(D46<$C$33,$A$33,IF(D46>$C$34,$A$37,$A$34))) | F46: =IF(D46="","",IF(E46<$C$33,$A$33,IF(E46>$C$34,$A$37,$A$34)))
C47: =IF(A47="","",IF(B47<$C$33,$A$33,IF(B47>$C$34,$A$37,$A$34))) | D47: =IF(B47="","",ROUNDUP(B47/12,0))
...

Sheet Table
A1: Phase 1 Risk Bounds | J1: Medium-term split | O1: asset_class | P1: asset_subgroup | Q1: sub_category | R1: recommended_fund | S1: isin | T1: Rank
A2: score | B2: eq_min | C2: eq_max | D2: debt_min | E2: debt_max | F2: others_min | G2: others_max | J2: horizon_years | K2: risk_bucket | L2: equity_pct | M2: debt_pct | O2: equity | P2: low_beta_equities | Q2: Large Cap Fund | R2: Nippon India Large Cap Fund - Growth Plan - Growth Option | S2: INF204K01562 | T2: 1
A3: 10 | B3: 70 | C3: 100 | D3: 0 | E3: 20 | F3: 0 | G3: 10 | J3: 5 | K3: Low | L3: 50 | M3: 50 | O3: equity | P3: low_beta_equities | Q3: Large Cap Fund | R3: Large Cap Fund_2 | T3: 2
A4: 9.5 | B4: 65 | C4: 100 | D4: 0 | E4: 25 | F4: 0 | G4: 10 | J4: 5 | K4: Medium | L4: 70 | M4: 30 | O4: equity | P4: medium_beta_equities | Q4: Flexi Cap Fund | R4: Parag Parikh Flexi Cap Fund - Direct Plan - Growth | S4: INF879O01027 | T4: 1
A5: 9 | B5: 60 | C5: 100 | D5: 0 | E5: 30 | F5: 0 | G5: 10 | J5: 5 | K5: High | L5: 80 | M5: 20 | O5: equity | P5: medium_beta_equities | Q5: Flexi Cap Fund | R5: Flexi Cap Fund_2 | T5: 2
A6: 8.5 | B6: 60 | C6: 90 | D6: 5 | E6: 30 | F6: 0 | G6: 10 | J6: 4 | K6: Low | L6: 35 | M6: 65 | O6: equity | P6: high_beta_equities | Q6: Small Cap Fund | R6: Nippon India Small Cap Fund - Growth Plan - Growth Option | S6: INF204K01HY3 | T6: 1
A7: 8 | B7: 55 | C7: 85 | D7: 10 | E7: 30 | F7: 0 | G7: 15 | J7: 4 | K7: Medium | L7: 50 | M7: 50 | O7: equity | P7: high_beta_equities | Q7: Small Cap Fund | R7: Small Cap Fund_2 | T7: 2
A8: 7.5 | B8: 50 | C8: 80 | D8: 10 | E8: 35 | F8: 5 | G8: 15 | J8: 4 | K8: High | L8: 65 | M8: 35 | O8: equity | P8: value_equities | Q8: Contra Fund | R8: SBI Contra Fund - Direct Plan - Growth | S8: INF200K01RA0 | T8: 1
A9: 7 | B9: 45 | C9: 75 | D9: 15 | E9: 40 | F9: 5 | G9: 15 | J9: 3 | K9: Low | L9: 0 | M9: 100 | O9: equity | P9: value_equities | Q9: Contra Fund | R9: Contra Fund_2 | T9: 2
A10: 6.5 | B10: 40 | C10: 70 | D10: 20 | E10: 45 | F10: 5 | G10: 15 | J10: 3 | K10: Medium | L10: 0 | M10: 100 | O10: equity | P10: dividend_equities | Q10: Dividend Yield Fund | R10: ICICI Prudential Dividend Yield Equity Fund - Growth Option | S10: INF109KA1TX4 | T10: 1
A11: 6 | B11: 35 | C11: 65 | D11: 25 | E11: 50 | F11: 5 | G11: 15 | J11: 3 | K11: High | L11: 0 | M11: 100 | O11: equity | P11: dividend_equities | Q11: Dividend Yield Fund | R11: Dividend Yield Fund_2 | T11: 2
A12: 5.5 | B12: 30 | C12: 60 | D12: 30 | E12: 55 | F12: 5 | G12: 15 | O12: equity | P12: tax_efficient_equities | Q12: ELSS Tax Saver Fund | R12: Motilal Oswal ELSS Tax Saver Fund - Regular Plan - Growth Option | S12: INF247L01544 | T12: 1
A13: 5 | B13: 30 | C13: 60 | D13: 30 | E13: 60 | F13: 5 | G13: 15 | O13: equity | P13: tax_efficient_equities | Q13: ELSS Tax Saver Fund | R13: ELSS Tax Saver Fund_2 | T13: 2
A14: 4.5 | B14: 25 | C14: 55 | D14: 35 | E14: 65 | F14: 5 | G14: 15 | O14: equity | P14: sector_equities | Q14: Sectoral Fund | R14: Tata Digital India Fund - Regular Plan - Growth | S14: INF277K01Z44 | T14: 1
A15: 4 | B15: 20 | C15: 55 | D15: 35 | E15: 70 | F15: 5 | G15: 15 | O15: equity | P15: sector_equities | Q15: Sectoral Fund | R15: Sectoral Fund_2 | T15: 2
A16: 3.5 | B16: 15 | C16: 50 | D16: 40 | E16: 70 | F16: 5 | G16: 15 | O16: equity | P16: us_equities | Q16: US Linked (FoF) | R16: Kotak US Specific Equity Passive FOF - Direct Plan - Growth | S16: INF174KA1FQ7 | T16: 1
A17: 3 | B17: 15 | C17: 45 | D17: 40 | E17: 75 | F17: 5 | G17: 15 | O17: equity | P17: us_equities | Q17: US Linked (FoF) | R17: US Linked (FoF)_2 | T17: 2
A18: 2.5 | B18: 10 | C18: 45 | D18: 40 | E18: 80 | F18: 5 | G18: 15 | O18: equity | P18: multi_asset | Q18: Multi Cap Fund | R18: ICICI Prudential Multicap Fund - Growth | S18: INF109K01613 | T18: 1
A19: 2 | B19: 10 | C19: 40 | D19: 40 | E19: 85 | F19: 5 | G19: 15 | O19: equity | P19: multi_asset | Q19: Multi Cap Fund | R19: Multi Cap Fund_2 | T19: 2
A20: 1.5 | B20: 5 | C20: 35 | D20: 45 | E20: 90 | F20: 5 | G20: 15 | O20: equity | P20: multi_asset | Q20: Multi Cap Fund | R20: Multi Cap Fund_3 | T20: 3
A21: 1 | B21: 5 | C21: 30 | D21: 45 | E21: 95 | F21: 5 | G21: 15 | O21: debt | P21: short_debt | Q21: Liquid Fund | R21: Canara Robeco Liquid Fund - Regular Plan - Growth Option | S21: INF179K01VF7 | T21: 1
O22: debt | P22: short_debt | Q22: Liquid Fund | R22: Liquid Fund_2 | T22: 2
A23: 1 | B23: =A23+1 -> 2 | C23: =B23+1 -> 3 | D23: =C23+1 -> 4 | E23: =D23+1 -> 5 | F23: =E23+1 -> 6 | G23: =F23+1 -> 7 | H23: =G23+1 -> 8 | I23: =H23+1 -> 9 | ... M23: =L23+1 -> 13 | O23: debt | P23: arbitrage | Q23: Arbitrage Fund | R23: Nippon India Arbitrage Fund - Direct Plan - Growth | S23: INF204K01XZ7 | T23: 1
A24: Score | B24: us_equities | C24: us_equities | D24: low_beta_equities | E24: low_beta_equities | F24: medium_beta_equities | G24: medium_beta_equities | H24: high_beta_equities | I24: high_beta_equities | J24: sector_equities | K24: sector_equities | L24: value_equities | M24: value_equities | O24: debt | P24: arbitrage | Q24: Arbitrage Fund | R24: Arbitrage Fund_2 | T24: 2
B25: min | C25: max | D25: min | E25: max | F25: min | G25: max | H25: min | I25: max | J25: min | K25: max | L25: min | M25: max | O25: debt | P25: arbitrage_plus_income | Q25: Arbitrage Fund | R25: HDFC Arbitrage Fund - Wholesale Growth | S25: INF179KB1HP6 | T25: 1
A26: 10 | B26: 20 | C26: 40 | D26: 0 | E26: 20 | F26: 30 | G26: 50 | H26: 10 | I26: 30 | J26: 0 | K26: 20 | L26: 0 | M26: 30 | O26: debt | P26: arbitrage_plus_income | Q26: Arbitrage Fund | R26: Arbitrage Fund_2 | T26: 2
A27: 9.5 | B27: 20 | C27: 40 | D27: 0 | E27: 20 | F27: 30 | G27: 50 | H27: 10 | I27: 30 | J27: 0 | K27: 20 | L27: 0 | M27: 30 | O27: debt | P27: arbitrage_plus_income | Q27: Arbitrage Fund | R27: Arbitrage Fund_3 | T27: 3
A28: 9 | B28: 20 | C28: 40 | D28: 0 | E28: 25 | F28: 25 | G28: 50 | H28: 10 | I28: 30 | J28: 0 | K28: 20 | L28: 0 | M28: 30 | O28: others | P28: gold_commodities | Q28: Gold ETF | R28: ICICI Prudential Gold ETF | S28: INF109KC1NT3 | T28: 1
A29: 8.5 | B29: 20 | C29: 40 | D29: 0 | E29: 30 | F29: 25 | G29: 45 | H29: 10 | I29: 30 | J29: 0 | K29: 20 | L29: 0 | M29: 30 | O29: others | P29: gold_commodities | Q29: Gold ETF | R29: Gold ETF_2 | T29: 2
A30: 8 | B30: 20 | C30: 40 | D30: 10 | E30: 30 | F30: 20 | G30: 40 | H30: 5 | I30: 25 | J30: 0 | K30: 20 | L30: 0 | M30: 30 | O30: others | P30: silver_commodities | Q30: Silver Linked (Index/ETF) | R30: ICICI Prudential Silver ETF | S30: INF109KC1Y56 | T30: 1
A31: 7.5 | B31: 20 | C31: 40 | D31: 15 | E31: 35 | F31: 20 | G31: 40 | H31: 5 | I31: 25 | J31: 0 | K31: 20 | L31: 0 | M31: 30 | O31: others | P31: silver_commodities | Q31: Silver Linked (Index/ETF) | R31: Silver Linked (Index/ETF)_2 | T31: 2
A32: 7 | B32: 20 | C32: 40 | D32: 20 | E32: 40 | F32: 20 | G32: 40 | H32: 5 | I32: 25 | J32: 0 | K32: 20 | L32: 0 | M32: 30 | O32: others | P32: china_equities | Q32: China Linked (FoF) | R32: Edelweiss Greater China Equity Off-shore Fund - Direct Plan - Growth | S32: INF843K01138 | T32: 1
A33: 6.5 | B33: 20 | C33: 40 | D33: 25 | E33: 45 | F33: 20 | G33: 40 | H33: 5 | I33: 20 | J33: 0 | K33: 20 | L33: 0 | M33: 30 | O33: others | P33: china_equities | Q33: China Linked (FoF) | R33: China Linked (FoF)_2 | T33: 2
A34: 6 | B34: 20 | C34: 40 | D34: 30 | E34: 50 | F34: 15 | G34: 35 | H34: 5 | I34: 20 | J34: 0 | K34: 20 | L34: 0 | M34: 30 | O34: others | P34: others_fofs | Q34: Others (FoF) | R34: Motilal Oswal Nasdaq 100 Fund of Fund - Direct Plan Growth | S34: INF247L01718 | T34: 1
A35: 5.5 | B35: 20 | C35: 40 | D35: 30 | E35: 55 | F35: 10 | G35: 35 | H35: 5 | I35: 20 | J35: 0 | K35: 20 | L35: 0 | M35: 30 | O35: others | P35: others_fofs | Q35: Others (FoF) | R35: Others (FoF)_2 | T35: 2
A36: 5 | B36: 20 | C36: 40 | D36: 35 | E36: 55 | F36: 10 | G36: 30 | H36: 0 | I36: 20 | J36: 0 | K36: 0 | L36: 0 | M36: 30 | O36: others | P36: others | Q36: Others (Index/ETF) | R36: Motilal Oswal Nasdaq 100 ETF | S36: INF247L01AP3 | T36: 1
A37: 4.5 | B37: 20 | C37: 40 | D37: 40 | E37: 60 | F37: 5 | G37: 25 | H37: 0 | I37: 20 | J37: 0 | K37: 0 | L37: 0 | M37: 30 | O37: others | P37: others | Q37: Others (Index/ETF) | R37: Others (Index/ETF)_2 | T37: 2
A38: 4 | B38: 20 | C38: 40 | D38: 45 | E38: 65 | F38: 5 | G38: 25 | H38: 0 | I38: 0 | J38: 0 | K38: 0 | L38: 0 | M38: 30
A39: 3.5 | B39: 20 | C39: 40 | D39: 50 | E39: 70 | F39: 0 | G39: 20 | H39: 0 | I39: 0 | J39: 0 | K39: 0 | L39: 0 | M39: 30
A40: 3 | B40: 20 | C40: 40 | D40: 55 | E40: 75 | F40: 0 | G40: 20 | H40: 0 | I40: 0 | J40: 0 | K40: 0 | L40: 0 | M40: 30
...

Sheet Guardrails
A1: Check | B1: Status
A2: step totals match | B2: OK
A3: asset class pct sum | B3: OK
A4: equity subgroup bounds | B4: OK
A5: all mapped | B5: OK
A6: multiples of 100 | B6: OK

Sheet c

Sheet d

Sheet e
A1: subgroup | B1: emergency | C1: short_term | D1: medium_term | E1: long_term | F1: total | H1: grand_total | I1: matches_corpus
A2: debt_subgroup | B2: 0 | C2: 0 | D2: 0 | E2: 0 | F2: =SUM(B2:E2) -> 0 | H2: =SUM(F2:F14) -> 0 | I2: =H2=ROUND(Allocation!B11,-2) -> TRUE
A3: short_debt | B3: 0 | C3: 0 | D3: 0 | E3: 0 | F3: =SUM(B3:E3) -> 0
A4: arbitrage_income | B4: 0 | C4: 0 | D4: 0 | E4: 0 | F4: =SUM(B4:E4) -> 0
A5: arbitrage_plus_income | B5: 0 | C5: 0 | D5: 0 | E5: 0 | F5: =SUM(B5:E5) -> 0
A6: tax_efficient_equities | B6: 0 | C6: 0 | D6: 0 | E6: 0 | F6: =SUM(B6:E6) -> 0
A7: multi_asset | B7: 0 | C7: 0 | D7: 0 | E7: 0 | F7: =SUM(B7:E7) -> 0
A8: low_beta_equities | B8: 0 | C8: 0 | D8: 0 | E8: 0 | F8: =SUM(B8:E8) -> 0
A9: medium_beta_equities | B9: 0 | C9: 0 | D9: 0 | E9: 0 | F9: =SUM(B9:E9) -> 0
A10: high_beta_equities | B10: 0 | C10: 0 | D10: 0 | E10: 0 | F10: =SUM(B10:E10) -> 0
A11: value_equities | B11: 0 | C11: 0 | D11: 0 | E11: 0 | F11: =SUM(B11:E11) -> 0
A12: sector_equities | B12: 0 | C12: 0 | D12: 0 | E12: 0 | F12: =SUM(B12:E12) -> 0
A13: us_equities | B13: 0 | C13: 0 | D13: 0 | E13: 0 | F13: =SUM(B13:E13) -> 0
A14: gold_commodities | B14: 0 | C14: 0 | D14: 0 | E14: 0 | F14: =SUM(B14:E14) -> 0

Sheet g
A1: Field | B1: Value
A2: grand_total | B2: =e!H2 -> 0
A3: matches_corpus | B3: =e!I2 -> TRUE
A4: step1_emergency | B4: =Allocation!B124 -> 180000
A5: step2_short_term | B5: =Allocation!B142 -> 300000
A6: step3_medium_term | B6: =Allocation!B171 -> arbitrage_plus_income
A7: step4_long_term | B7: =d!B13 -> 0

Sheet  

Sheet f

Sheet a
